Workbook

Sheet Financials
A1: The Home Depot, Inc. | B1: ACTUAL | H1: FORECAST
A2: Balance Sheet (in millions) | B2: 43863 | C2: 44227 | D2: 44591 | E2: 44955 | F2: 45319 | G2: 45690 | H2: 46053 | I2: 46418 | J2: 46783 | K2: 47149 | L2: 47514
A4: ASSETS
A5: Cash and cash equivalents | B5: =B134 -> 2133 | C5: =C134 -> 7895 | D5: =D134 -> 2343 | E5: =E134 -> 2757 | F5: =F134 -> 3760 | G5: =G134 -> 1659 | H5: =H134 -> 2600 | I5: =I134 -> 2600 | ... L5: =L134 -> 2600
A6: Short-term investments | B6: 0 | C6: 0 | D6: 0 | E6: 0 | F6: 0 | G6: 0 | H6: =G6+Financing!H139 -> 965.07883 | I6: =H6+Financing!I139 -> 1431.5134 | J6: =I6+Financing!J139 -> 4733.0502 | K6: =J6+Financing!K139 -> 10762.567 | L6: =K6+Financing!L139 -> 17202.781
A7: Receivables, net | B7: 2106 | C7: 2992 | D7: 3426 | E7: 3317 | F7: 3328 | G7: 4903 | H7: ='Working Capital'!H4 -> 3756.5375 | I7: ='Working Capital'!I4 -> 4041.4541 | J7: ='Working Capital'!J4 -> 4348.1289 | K7: ='Working Capital'!K4 -> 4678.2338 | L7: ='Working Capital'!L4 -> 5033.57
A8: Merchandise inventories | B8: 14531 | C8: 16627 | D8: 22068 | E8: 24886 | F8: 20976 | G8: 23451 | H8: ='Working Capital'!H8 -> 23277.426 | I8: ='Working Capital'!I8 -> 25042.915 | J8: ='Working Capital'!J8 -> 26943.229 | K8: ='Working Capital'!K8 -> 28988.727 | L8: ='Working Capital'!L8 -> 31190.572
A9: Other current assets | B9: 1040 | C9: 963 | D9: 1218 | E9: 1511 | F9: 1711 | G9: 1670 | H9: ='Working Capital'!H12 -> 1595.9408 | I9: ='Working Capital'!I12 -> 1716.9857 | J9: ='Working Capital'!J12 -> 1847.2745 | K9: ='Working Capital'!K12 -> 1987.5175 | L9: ='Working Capital'!L12 -> 2138.4798
A10: Total current assets | B10: =SUM(B5:B9) -> 19810 | C10: =SUM(C5:C9) -> 28477 | D10: =SUM(D5:D9) -> 29055 | E10: =SUM(E5:E9) -> 32471 | F10: =SUM(F5:F9) -> 29775 | G10: =SUM(G5:G9) -> 31683 | H10: =SUM(H5:H9) -> 32194.983 | I10: =SUM(I5:I9) -> 34832.868 | ... L10: =SUM(L5:L9) -> 58165.403
A12: Net property and equipment | B12: 22770 | C12: 24705 | D12: 25199 | E12: 25631 | F12: 26154 | G12: 26702 | H12: ='Long Term Asset & Liab'!H15 -> 27196.248 | I12: ='Long Term Asset & Liab'!I15 -> 27763.533 | J12: ='Long Term Asset & Liab'!J15 -> 28410.019 | K12: ='Long Term Asset & Liab'!K15 -> 29142.409 | L12: ='Long Term Asset & Liab'!L15 -> 29967.996
A13: Operating lease right-of-use assets | B13: 5595 | C13: 5962 | D13: 5968 | E13: 6941 | F13: 7884 | G13: 8592 | H13: 8592 | I13: 8592 | J13: 8592 | K13: 8592 | L13: 8592
A14: Goodwill | B14: 2254 | C14: 7126 | D14: 7449 | E14: 7444 | F14: 8455 | G14: 19475 | H14: ='Long Term Asset & Liab'!H113 -> 19475 | I14: ='Long Term Asset & Liab'!I113 -> 19475 | J14: ='Long Term Asset & Liab'!J113 -> 19475 | K14: ='Long Term Asset & Liab'!K113 -> 19475 | L14: ='Long Term Asset & Liab'!L113 -> 19475
A15: Intangible assets | B15: 0 | C15: 3612 | D15: 3503 | E15: 3323 | F15: 3606 | G15: 8983 | H15: ='Long Term Asset & Liab'!H106 -> 8430 | I15: ='Long Term Asset & Liab'!I106 -> 7877 | J15: ='Long Term Asset & Liab'!J106 -> 7332 | K15: ='Long Term Asset & Liab'!K106 -> 6804 | L15: ='Long Term Asset & Liab'!L106 -> 6318
A16: Other assets | B16: 807 | C16: 699 | D16: 702 | E16: =3958-3323 -> 635 | F16: =4262-3606 -> 656 | G16: 684 | H16: ='Long Term Asset & Liab'!H121 -> 772.2294 | I16: ='Long Term Asset & Liab'!I121 -> 830.79955 | J16: ='Long Term Asset & Liab'!J121 -> 893.84252 | K16: ='Long Term Asset & Liab'!K121 -> 961.70201 | L16: ='Long Term Asset & Liab'!L121 -> 1034.7483
A17: Total assets | B17: =SUM(B10:B16) -> 51236 | C17: =SUM(C10:C16) -> 70581 | D17: =SUM(D10:D16) -> 71876 | E17: =SUM(E10:E16) -> 76445 | F17: =SUM(F10:F16) -> 76530 | G17: =SUM(G10:G16) -> 96119 | H17: =SUM(H10:H16) -> 96660.46 | I17: =SUM(I10:I16) -> 99371.2 | ... L17: =SUM(L10:L16) -> 123553.15
A19: LIABILITIES
A21: Short-term debt | B21: 974 | C21: 0 | D21: 1035 | E21: 0 | F21: 0 | G21: 316 | H21: 316 | I21: 316 | J21: 316 | K21: 316 | L21: 316
A22: Accounts payable | B22: 7787 | C22: 11606 | D22: 13462 | E22: 11443 | F22: 10037 | G22: 11938 | H22: ='Working Capital'!H16 -> 12861.806 | I22: ='Working Capital'!I16 -> 13837.316 | J22: ='Working Capital'!J16 -> 14887.324 | K22: ='Working Capital'!K16 -> 16017.552 | L22: ='Working Capital'!L16 -> 17234.168
A23: Accrued salaries and related expenses | B23: 1494 | C23: 2463 | D23: 2426 | E23: 1991 | F23: 2096 | G23: 2315 | H23: ='Working Capital'!H20 -> 2591.293 | I23: ='Working Capital'!I20 -> 2787.831 | J23: ='Working Capital'!J20 -> 2999.378 | K23: ='Working Capital'!K20 -> 3227.0873 | L23: ='Working Capital'!L20 -> 3472.2013
A24: Sales taxes payable | B24: 605 | C24: 774 | D24: 848 | E24: 528 | F24: 449 | G24: 628 | H24: ='Working Capital'!H24 -> 737.90809 | I24: ='Working Capital'!I24 -> 793.87513 | J24: ='Working Capital'!J24 -> 854.11619 | K24: ='Working Capital'!K24 -> 918.9597 | L24: ='Working Capital'!L24 -> 988.75947
A25: Deferred revenue | B25: 2116 | C25: 2823 | D25: 3596 | E25: 3064 | F25: 2762 | G25: 2610 | H25: ='Working Capital'!H28 -> 3397.8094 | I25: ='Working Capital'!I28 -> 3655.518 | J25: ='Working Capital'!J28 -> 3932.9071 | K25: ='Working Capital'!K28 -> 4231.4889 | L25: ='Working Capital'!L28 -> 4552.8924
A26: Income taxes payable | B26: 55 | C26: 193 | D26: 158 | E26: 50 | F26: 28 | G26: 832 | H26: ='Working Capital'!H32 -> 289.79899 | I26: ='Working Capital'!I32 -> 316.50851 | J26: ='Working Capital'!J32 -> 345.84095 | K26: ='Working Capital'!K32 -> 374.17873 | L26: ='Working Capital'!L32 -> 402.00635
A27: Current installments of long-term debt | B27: 1839 | C27: 1416 | D27: 2447 | E27: 1231 | F27: 1368 | G27: 4582 | H27: =Financing!H9 -> 4845 | I27: =Financing!I9 -> 3769 | J27: =Financing!J9 -> 2727 | K27: =Financing!K9 -> 3946 | L27: =Financing!L9 -> 3946
A28: Current operating lease liabilities | B28: 828 | C28: 828 | D28: 830 | E28: 945 | F28: 1050 | G28: 1274 | H28: 1274 | I28: 1274 | J28: 1274 | K28: 1274 | L28: 1274
A29: Other accrued expenses | B29: 2677 | C29: 3063 | D29: 3891 | E29: 3858 | F29: 4225 | G29: 4166 | H29: ='Working Capital'!H36 -> 4358.8059 | I29: ='Working Capital'!I36 -> 4689.4019 | J29: ='Working Capital'!J36 -> 5045.2445 | K29: ='Working Capital'!K36 -> 5428.2736 | L29: ='Working Capital'!L36 -> 5840.5792
A30: Total current liabilities | B30: =SUM(B21:B29) -> 18375 | C30: =SUM(C21:C29) -> 23166 | D30: =SUM(D21:D29) -> 28693 | E30: =SUM(E21:E29) -> 23110 | F30: =SUM(F21:F29) -> 22015 | G30: =SUM(G21:G29) -> 28661 | H30: =SUM(H21:H29) -> 30672.421 | I30: =SUM(I21:I29) -> 31439.451 | ... L30: =SUM(L21:L29) -> 38026.607
A32: Long-term debt | B32: 28670 | C32: 35822 | D32: 36604 | E32: 41962 | F32: 42743 | G32: 48485 | H32: =Financing!H21 -> 43640 | I32: =Financing!I21 -> 39871 | J32: =Financing!J21 -> 37144 | K32: =Financing!K21 -> 33198 | L32: =Financing!L21 -> 29252
A33: Long-term operating lease liabilities | B33: 5066 | C33: 5356 | D33: 5353 | E33: 6226 | F33: 7082 | G33: 7633 | H33: 7633 | I33: 7633 | J33: 7633 | K33: 7633 | L33: 7633
A34: Deferred income taxes | B34: 706 | C34: 1131 | D34: 909 | E34: 1019 | F34: 863 | G34: 1962 | H34: ='Long Term Asset & Liab'!H131 -> 1575.8957 | I34: ='Long Term Asset & Liab'!I131 -> 1576.3042 | J34: ='Long Term Asset & Liab'!J131 -> 1579.2067 | K34: ='Long Term Asset & Liab'!K131 -> 1585.0523 | L34: ='Long Term Asset & Liab'!L131 -> 1594.7645
A35: Other long-term liabilities | B35: 1535 | C35: 1807 | D35: 2013 | E35: 2566 | F35: 2783 | G35: 2738 | H35: ='Long Term Asset & Liab'!H126 -> 2694.2226 | I35: ='Long Term Asset & Liab'!I126 -> 2898.5673 | J35: ='Long Term Asset & Liab'!J126 -> 3118.5173 | K35: ='Long Term Asset & Liab'!K126 -> 3355.2715 | L35: ='Long Term Asset & Liab'!L126 -> 3610.1218
A36: Total liabilities | B36: =SUM(B30:B35) -> 54352 | C36: =SUM(C30:C35) -> 67282 | D36: =SUM(D30:D35) -> 73572 | E36: =SUM(E30:E35) -> 74883 | F36: =SUM(F30:F35) -> 75486 | G36: =SUM(G30:G35) -> 89479 | H36: =SUM(H30:H35) -> 86215.539 | I36: =SUM(I30:I35) -> 83418.323 | ... L36: =SUM(L30:L35) -> 80116.493
A38: SHAREHOLDERS' EQUITY
A39: Common stock | B39: 89 | C39: 89 | D39: 90 | E39: 90 | F39: 90 | G39: 90 | H39: =Financing!H49 -> 90 | I39: =Financing!I49 -> 90 | J39: =Financing!J49 -> 90 | K39: =Financing!K49 -> 90 | L39: =Financing!L49 -> 90
A40: Paid-in capital | B40: 11001 | C40: 11540 | D40: 12132 | E40: 12592 | F40: 13147 | G40: 14117 | H40: =Financing!H50 -> 14811.189 | I40: =Financing!I50 -> 15560.124 | J40: =Financing!J50 -> 16368.218 | K40: =Financing!K50 -> 17240.231 | L40: =Financing!L50 -> 18181.727
A41: Retained earnings | B41: 51729 | C41: 58134 | D41: 67580 | E41: 76896 | F41: 83656 | G41: 89533 | H41: =G41+H79+Financing!H103 -> 98843.732 | I41: =H41+I79+Financing!I103 -> 109802.75 | J41: =I41+J79+Financing!J103 -> 122559.79 | K41: =J41+K79+Financing!K103 -> 137057.06 | L41: =K41+L79+Financing!L103 -> 153264.93
A42: Accumulated other comp. income (loss) | B42: -739 | C42: -671 | D42: -704 | E42: -718 | F42: -477 | G42: -1129 | H42: -1129 | I42: -1129 | J42: -1129 | K42: -1129 | L42: -1129
A43: Treasury stock | B43: -65196 | C43: -65793 | D43: -80794 | E43: -87298 | F43: -95372 | G43: -95971 | H43: =Financing!H82 -> -102171 | I43: =Financing!I82 -> -108371 | J43: =Financing!J82 -> -114571 | K43: =Financing!K82 -> -120771 | L43: =Financing!L82 -> -126971
A44: Total shareholders equity | B44: =SUM(B39:B43) -> -3116 | C44: =SUM(C39:C43) -> 3299 | D44: =SUM(D39:D43) -> -1696 | E44: =SUM(E39:E43) -> 1562 | F44: =SUM(F39:F43) -> 1044 | G44: =SUM(G39:G43) -> 6640 | H44: =SUM(H39:H43) -> 10444.921 | I44: =SUM(I39:I43) -> 15952.878 | ... L44: =SUM(L39:L43) -> 43436.654
A46: Total liabilities & equity | B46: =B36+B44 -> 51236 | C46: =C36+C44 -> 70581 | D46: =D36+D44 -> 71876 | E46: =E36+E44 -> 76445 | F46: =F36+F44 -> 76530 | G46: =G36+G44 -> 96119 | H46: =H36+H44 -> 96660.46 | I46: =I36+I44 -> 99371.2 | ... L46: =L36+L44 -> 123553.15
B48: =IF(B46=B17,"BALANCE","ERROR") -> BALANCE | C48: =IF(C46=C17,"BALANCE","ERROR") -> BALANCE | D48: =IF(D46=D17,"BALANCE","ERROR") -> BALANCE | E48: =IF(E46=E17,"BALANCE","ERROR") -> BALANCE | F48: =IF(F46=F17,"BALANCE","ERROR") -> BALANCE | G48: =IF(G46=G17,"BALANCE","ERROR") -> BALANCE | H48: =IF(H46=H17,"BALANCE","ERROR") -> BALANCE | I48: =IF(I46=I17,"BALANCE","ERROR") -> BALANCE | ... L48: =IF(L46=L17,"BALANCE","ERROR") -> BALANCE
...

Sheet Revenue
A1: The Home Depot, Inc. | B1: ACTUAL | H1: FORECAST
A2: (in millions) | B2: 43863 | C2: 44227 | D2: 44591 | E2: 44955 | F2: 45319 | G2: 45690 | H2: 46053 | I2: 46418 | J2: 46783 | K2: 47149 | L2: 47514
A4: FINAL REVENUE FORECAST (average of 4 methods)
A6: Net sales | B6: =Financials!B55 -> 110225 | C6: =Financials!C55 -> 132110 | D6: =Financials!D55 -> 151157 | E6: =Financials!E55 -> 157403 | F6: =Financials!F55 -> 152669 | G6: =Financials!G55 -> 159514 | H6: =AVERAGE(H13,H26,H44,H77) -> 171606.53 | I6: =AVERAGE(I13,I26,I44,I77) -> 184622.12 | J6: =AVERAGE(J13,J26,J44,J77) -> 198631.67 | K6: =AVERAGE(K13,K26,K44,K77) -> 213711.56 | L6: =AVERAGE(L13,L26,L44,L77) -> 229944.06
A11: FORECAST METHOD 1--BASED ON REVENUE GROWTH
A13: Net sales from income statement: | B13: =Financials!B55 -> 110225 | C13: =Financials!C55 -> 132110 | D13: =Financials!D55 -> 151157 | E13: =Financials!E55 -> 157403 | F13: =Financials!F55 -> 152669 | G13: =Financials!G55 -> 159514 | H13: =G13*(1+H15) -> 172275.12 | I13: =H13*(1+I15) -> 186057.13 | J13: =I13*(1+J15) -> 200941.7 | K13: =J13*(1+K15) -> 217017.04 | L13: =K13*(1+L15) -> 234378.4
A15: Sales Growth: | C15: =(C13-B13)/B13 -> 0.19854842 | D15: =(D13-C13)/C13 -> 0.14417531 | E15: =(E13-D13)/D13 -> 0.041321275 | F15: =(F13-E13)/E13 -> -0.030075666 | G15: =(G13-F13)/F13 -> 0.044835559 | H15: 0.08 | I15: 0.08 | J15: 0.08 | K15: 0.08 | L15: 0.08
A19: FORECAST METHOD 2--BASED ON REVENUE GROWTH BY PRODUCT TYPE
A21: Sales by product type:
A22: Building materials | B22: 39337 | C22: 46521 | D22: 54990 | E22: 54572 | F22: 52661 | G22: 52756 | H22: =G22*(1+H29) -> 56174.589 | I22: =H22*(1+I29) -> 59814.702 | J22: =I22*(1+J29) -> 63690.695 | K22: =J22*(1+K29) -> 67817.852 | L22: =K22*(1+L29) -> 72212.449
A23: Décor | B23: 37386 | C23: 43415 | D23: 50437 | E23: 54442 | F23: 51945 | G23: 51790 | H23: =G23*(1+H30) -> 55451.553 | I23: =H23*(1+I30) -> 59371.978 | J23: =I23*(1+J30) -> 63569.577 | K23: =J23*(1+K30) -> 68063.946 | L23: =K23*(1+L30) -> 72876.067
A24: Hardlines | B24: 33502 | C24: 42174 | D24: 45730 | E24: 48389 | F24: 48063 | G24: 48562 | H24: =G24*(1+H31) -> 52495.522 | I24: =H24*(1+I31) -> 56747.659 | J24: =I24*(1+J31) -> 61344.22 | K24: =J24*(1+K31) -> 66313.101 | L24: =K24*(1+L31) -> 71684.463
A25: Other | G25: 6406 | H25: =G25*(1+H32) -> 6918.48 | I25: =H25*(1+I32) -> 7471.9584 | J25: =I25*(1+J32) -> 8069.7151 | K25: =J25*(1+K32) -> 8715.2923 | L25: =K25*(1+L32) -> 9412.5157
B26: =SUM(B22:B25) -> 110225 | C26: =SUM(C22:C25) -> 132110 | D26: =SUM(D22:D25) -> 151157 | E26: =SUM(E22:E25) -> 157403 | F26: =SUM(F22:F25) -> 152669 | G26: =SUM(G22:G25) -> 159514 | H26: =SUM(H22:H25) -> 171040.14 | I26: =SUM(I22:I25) -> 183406.3 | ... L26: =SUM(L22:L25) -> 226185.49
A28: Sales Growth:
A29: Building materials | C29: =(C22-B22)/B22 -> 0.18262704 | D29: =(D22-C22)/C22 -> 0.18204682 | E29: =(E22-D22)/D22 -> -0.0076013821 | F29: =(F22-E22)/E22 -> -0.035017958 | G29: =(G22-F22)/F22 -> 0.0018039916 | H29: 0.0648 | I29: 0.0648 | J29: 0.0648 | K29: 0.0648 | L29: 0.0648
A30: Décor | C30: =(C23-B23)/B23 -> 0.16126357 | D30: =(D23-C23)/C23 -> 0.16174133 | E30: =(E23-D23)/D23 -> 0.079405992 | F30: =(F23-E23)/E23 -> -0.045865325 | G30: =(G23-F23)/F23 -> -0.0029839253 | H30: 0.0707 | I30: 0.0707 | J30: 0.0707 | K30: 0.0707 | L30: 0.0707
A31: Hardlines | C31: =(C24-B24)/B24 -> 0.25885022 | D31: =(D24-C24)/C24 -> 0.084317352 | E31: =(E24-D24)/D24 -> 0.058145637 | F31: =(F24-E24)/E24 -> -0.0067370683 | G31: =(G24-F24)/F24 -> 0.010382207 | H31: 0.081 | I31: 0.081 | J31: 0.081 | K31: 0.081 | L31: 0.081
A32: Other | G32: 0 | H32: 0.08 | I32: 0.08 | J32: 0.08 | K32: 0.08 | L32: 0.08
A39: FORECAST METHOD 3--INCORPORATING STORE DATA AND GEOGRAPHIC SEGMENTS
A41: Sales by geographic segment:
A42: US | B42: 101333 | C42: 122158 | D42: 138920 | E42: 144840 | F42: 140083 | G42: 147007 | H42: =H47*H56 -> 158828.07 | I42: =I47*I56 -> 171599.69 | J42: =J47*J56 -> 185398.29 | K42: =K47*K56 -> 200306.47 | L42: =L47*L56 -> 216413.43
A43: Outside the US | B43: 8892 | C43: 9952 | D43: 12237 | E43: 12563 | F43: 12586 | G43: 12507 | H43: =H51*H57 -> 13437.725 | I43: =I51*I57 -> 14437.711 | J43: =J51*J57 -> 15512.112 | K43: =K51*K57 -> 16666.467 | L43: =L51*L57 -> 17906.724
A44: Total | B44: =B42+B43 -> 110225 | C44: =C42+C43 -> 132110 | D44: =D42+D43 -> 151157 | E44: =E42+E43 -> 157403 | F44: =F42+F43 -> 152669 | G44: =G42+G43 -> 159514 | H44: =SUM(H42:H43) -> 172265.79 | I44: =SUM(I42:I43) -> 186037.4 | J44: =SUM(J42:J43) -> 200910.4 | K44: =SUM(K42:K43) -> 216972.93 | L44: =SUM(L42:L43) -> 234320.15
A46: Number of stores:
A47: US | B47: 1984 | C47: 1987 | D47: 2006 | E47: 2007 | F47: 2015 | G47: 2025 | H47: =G47*(1+H61) -> 2033.3025 | I47: =H47*(1+I61) -> 2041.639 | J47: =I47*(1+J61) -> 2050.0098 | K47: =J47*(1+K61) -> 2058.4148 | L47: =K47*(1+L61) -> 2066.8543
A49: Canada | B49: 182 | C49: 182 | D49: 182 | E49: 182 | F49: 182 | G49: 182 | H49: 182 | I49: 182 | J49: 182 | K49: 182 | L49: 182
A50: Mexico | B50: 125 | C50: 127 | D50: 129 | E50: 133 | F50: 138 | G50: 140 | H50: =H51-H49 -> 143.0912 | I50: =I51-I49 -> 146.21208 | J50: =J51-J49 -> 149.36291 | K50: =K51-K49 -> 152.544 | L50: =L51-L49 -> 155.75562
A51: Total outside US | B51: =B49+B50 -> 307 | C51: =C49+C50 -> 309 | D51: =D49+D50 -> 311 | E51: =E49+E50 -> 315 | F51: =F49+F50 -> 320 | G51: =G49+G50 -> 322 | H51: =G51*(1+H62) -> 325.0912 | I51: =H51*(1+I62) -> 328.21208 | J51: =I51*(1+J62) -> 331.36291 | K51: =J51*(1+K62) -> 334.544 | L51: =K51*(1+L62) -> 337.75562
A53: Total stores | B53: =B47+B51 -> 2291 | C53: =C47+C51 -> 2296 | D53: =D47+D51 -> 2317 | E53: =E47+E51 -> 2322 | F53: =F47+F51 -> 2335 | G53: =G47+G51 -> 2347 | H53: =H47+H51 -> 2358.3937 | I53: =I47+I51 -> 2369.8511 | ... L53: =L47+L51 -> 2404.6099
A55: Sales per store
A56: US | B56: =B42/B47 -> 51.075101 | C56: =C42/C47 -> 61.478611 | D56: =D42/D47 -> 69.252243 | E56: =E42/E47 -> 72.167414 | F56: =F42/F47 -> 69.520099 | G56: =G42/G47 -> 72.596049 | H56: =G56*(1+H65) -> 78.113349 | I56: =H56*(1+I65) -> 84.049964 | J56: =I56*(1+J65) -> 90.437761 | K56: =J56*(1+K65) -> 97.311031 | L56: =K56*(1+L65) -> 104.70667
A57: Outside the US | B57: =B43/B51 -> 28.964169 | C57: =C43/C51 -> 32.20712 | D57: =D43/D51 -> 39.347267 | E57: =E43/E51 -> 39.88254 | F57: =F43/F51 -> 39.33125 | G57: =G43/G51 -> 38.841615 | H57: =G57*(1+H66) -> 41.335247 | I57: =H57*(1+I66) -> 43.988969 | J57: =I57*(1+J66) -> 46.813061 | K57: =J57*(1+K66) -> 49.81846 | L57: =K57*(1+L66) -> 53.016805
A59: Growth:
A60: Number of stores:
A61: US | C61: =(C47-B47)/B47 -> 0.0015120968 | D61: =(D47-C47)/C47 -> 0.009562154 | E61: =(E47-D47)/D47 -> 0.00049850449 | F61: =(F47-E47)/E47 -> 0.0039860488 | G61: =(G47-F47)/F47 -> 0.0049627792 | H61: 0.0041 | I61: 0.0041 | J61: 0.0041 | K61: 0.0041 | L61: 0.0041
A62: Outside the US | C62: =(C51-B51)/B51 -> 0.006514658 | D62: =(D51-C51)/C51 -> 0.0064724919 | E62: =(E51-D51)/D51 -> 0.012861736 | F62: =(F51-E51)/E51 -> 0.015873016 | G62: =(G51-F51)/F51 -> 0.00625 | H62: 0.0096 | I62: 0.0096 | J62: 0.0096 | K62: 0.0096 | L62: 0.0096
A64: Sales per store
A65: US | C65: =(C56-B56)/B56 -> 0.20369045 | D65: =(D56-C56)/C56 -> 0.1264445 | E65: =(E56-D56)/D56 -> 0.042094965 | F65: =(F56-E56)/E56 -> -0.036682966 | G65: =(G56-F56)/F56 -> 0.04424548 | H65: 0.076 | I65: 0.076 | J65: 0.076 | K65: 0.076 | L65: 0.076
A66: Outside the US | C66: =(C57-B57)/B57 -> 0.11196421 | D66: =(D57-C57)/C57 -> 0.22169468 | E66: =(E57-D57)/D57 -> 0.013603811 | F66: =(F57-E57)/E57 -> -0.013822833 | G66: =(G57-F57)/F57 -> -0.012449009 | H66: 0.0642 | I66: 0.0642 | J66: 0.0642 | K66: 0.0642 | L66: 0.0642
...

Sheet Expenses
A1: The Home Depot, Inc. | B1: ACTUAL | H1: FORECAST
A2: (in millions) | B2: 43863 | C2: 44227 | D2: 44591 | E2: 44955 | F2: 45319 | G2: 45690 | H2: 46053 | I2: 46418 | J2: 46783 | K2: 47149 | L2: 47514
A4: Revenue forecast: | B4: =Financials!B55 -> 110225 | C4: =Financials!C55 -> 132110 | D4: =Financials!D55 -> 151157 | E4: =Financials!E55 -> 157403 | F4: =Financials!F55 -> 152669 | G4: =Financials!G55 -> 159514 | H4: =Financials!H55 -> 171606.53 | I4: =Financials!I55 -> 184622.12 | ... L4: =Financials!L55 -> 229944.06
A7: COGS from income statement: | B7: =Financials!B57 -> 72653 | C7: =Financials!C57 -> 87257 | D7: =Financials!D57 -> 100325 | E7: =Financials!E57 -> 104625 | F7: =Financials!F57 -> 101709 | G7: =Financials!G57 -> 106206 | H7: =H4*H9 -> 113826.61 | I7: =I4*I9 -> 122459.85 | J7: =J4*J9 -> 131752.39 | K7: =K4*K9 -> 141754.88 | L7: =L4*L9 -> 152521.9
A9: As a % of revenue | B9: =B7/B4 -> 0.65913359 | C9: =C7/C4 -> 0.66048747 | D9: =D7/D4 -> 0.66371389 | E9: =E7/E4 -> 0.66469508 | F9: =F7/F4 -> 0.66620598 | G9: =G7/G4 -> 0.6658099 | H9: 0.6633 | I9: 0.6633 | J9: 0.6633 | K9: 0.6633 | L9: 0.6633
A13: SG&A from income statement: | B13: =Financials!B62 -> 19740 | C13: =Financials!C62 -> 24447 | D13: =Financials!D62 -> 25406 | E13: =Financials!E62 -> 26284 | F13: =Financials!F62 -> 26598 | G13: =Financials!G62 -> 28748 | H13: =H4*H15 -> 30134.107 | I13: =I4*I15 -> 32419.645 | J13: =J4*J15 -> 34879.722 | K13: =K4*K15 -> 37527.75 | L13: =L4*L15 -> 40378.177
A15: As a % of revenue | B15: =B13/B4 -> 0.17908823 | C15: =C13/C4 -> 0.18505034 | D15: =D13/D4 -> 0.1680769 | E15: =E13/E4 -> 0.16698538 | F15: =F13/F4 -> 0.17422004 | G15: =G13/G4 -> 0.18022243 | H15: 0.1756 | I15: 0.1756 | J15: 0.1756 | K15: 0.1756 | L15: 0.1756
A19: Tax expense forecast
A20: Tax Expense | B20: =Financials!B77 -> 3473 | C20: =Financials!C77 -> 4112 | D20: =Financials!D77 -> 5304 | E20: =Financials!E77 -> 5372 | F20: =Financials!F77 -> 4781 | G20: =Financials!G77 -> 4600 | H20: =H21*H22 -> 5307.6737 | I20: =I21*I22 -> 5796.8592 | J20: =J21*J22 -> 6334.0834 | K20: =K21*K22 -> 6853.0904 | L20: =L21*L22 -> 7362.7536
A21: Pretax income | B21: =Financials!B75 -> 14715 | C21: =Financials!C75 -> 16978 | D21: =Financials!D75 -> 21737 | E21: =Financials!E75 -> 22477 | F21: =Financials!F75 -> 19924 | G21: =Financials!G75 -> 19406 | H21: =Financials!H75 -> 22142.986 | I21: =Financials!I75 -> 24183.81 | ... L21: =Financials!L75 -> 30716.536
A22: Effective tax rate (ETR) | B22: =B20/B21 -> 0.23601767 | C22: =C20/C21 -> 0.24219578 | D22: =D20/D21 -> 0.24400791 | E22: =E20/E21 -> 0.23899987 | F22: =F20/F21 -> 0.23996186 | G22: =G20/G21 -> 0.23704009 | H22: 0.2397 | I22: 0.2397 | J22: 0.2397 | K22: 0.2397 | L22: 0.2397

Sheet Working Capital
A1: The Home Depot, Inc. | B1: ACTUAL | H1: FORECAST
A2: (in millions) | B2: 43863 | C2: 44227 | D2: 44591 | E2: 44955 | F2: 45319 | G2: 45690 | H2: 46053 | I2: 46418 | J2: 46783 | K2: 47149 | L2: 47514
A4: Accounts receivable | B4: =Financials!B7 -> 2106 | C4: =Financials!C7 -> 2992 | D4: =Financials!D7 -> 3426 | E4: =Financials!E7 -> 3317 | F4: =Financials!F7 -> 3328 | G4: =Financials!G7 -> 4903 | H4: =(Financials!H55/365)*'Working Capital'!H5 -> 3756.5375 | I4: =(Financials!I55/365)*'Working Capital'!I5 -> 4041.4541 | J4: =(Financials!J55/365)*'Working Capital'!J5 -> 4348.1289 | K4: =(Financials!K55/365)*'Working Capital'!K5 -> 4678.2338 | L4: =(Financials!L55/365)*'Working Capital'!L5 -> 5033.57
A5: Days sales in A/R | C5: =Ratios!C59 -> 7.0425025 | D5: =Ratios!D59 -> 7.7487976 | E5: =Ratios!E59 -> 7.8181324 | F5: =Ratios!F59 -> 7.9434103 | G5: =Ratios!G59 -> 9.4170888 | H5: 7.99 | I5: 7.99 | J5: 7.99 | K5: 7.99 | L5: 7.99
A6: 5 year average | G6: =AVERAGE(C5:G5) -> 7.9939863
A8: Merchandise inventories | B8: =Financials!B8 -> 14531 | C8: =Financials!C8 -> 16627 | D8: =Financials!D8 -> 22068 | E8: =Financials!E8 -> 24886 | F8: =Financials!F8 -> 20976 | G8: =Financials!G8 -> 23451 | H8: =Financials!H57/'Working Capital'!H9 -> 23277.426 | I8: =Financials!I57/'Working Capital'!I9 -> 25042.915 | J8: =Financials!J57/'Working Capital'!J9 -> 26943.229 | K8: =Financials!K57/'Working Capital'!K9 -> 28988.727 | L8: =Financials!L57/'Working Capital'!L9 -> 31190.572
A9: Inventory turnover | C9: =Ratios!C66 -> 5.6009372 | D9: =Ratios!D66 -> 5.1854245 | E9: =Ratios!E66 -> 4.4564893 | F9: =Ratios!F66 -> 4.4354367 | G9: =Ratios!G66 -> 4.7811466 | H9: 4.89 | I9: 4.89 | J9: 4.89 | K9: 4.89 | L9: 4.89
A10: 5 year average | G10: =AVERAGE(C9:G9) -> 4.8918869
A12: Other current assets | B12: =Financials!B9 -> 1040 | C12: =Financials!C9 -> 963 | D12: =Financials!D9 -> 1218 | E12: =Financials!E9 -> 1511 | F12: =Financials!F9 -> 1711 | G12: =Financials!G9 -> 1670 | H12: =Financials!H55*'Working Capital'!H13 -> 1595.9408 | I12: =Financials!I55*'Working Capital'!I13 -> 1716.9857 | J12: =Financials!J55*'Working Capital'!J13 -> 1847.2745 | K12: =Financials!K55*'Working Capital'!K13 -> 1987.5175 | L12: =Financials!L55*'Working Capital'!L13 -> 2138.4798
A13: Percentage of revenue | B13: =B12/Financials!B55 -> 0.0094352461 | C13: =C12/Financials!C55 -> 0.0072893801 | D13: =D12/Financials!D55 -> 0.0080578471 | E13: =E12/Financials!E55 -> 0.0095995629 | F13: =F12/Financials!F55 -> 0.011207252 | G13: =G12/Financials!G55 -> 0.010469301 | H13: 0.0093 | I13: 0.0093 | J13: 0.0093 | K13: 0.0093 | L13: 0.0093
A14: 5 year average | G14: =AVERAGE(C13:G13) -> 0.0093246686
A16: Accounts payable | B16: =Financials!B22 -> 7787 | C16: =Financials!C22 -> 11606 | D16: =Financials!D22 -> 13462 | E16: =Financials!E22 -> 11443 | F16: =Financials!F22 -> 10037 | G16: =Financials!G22 -> 11938 | H16: =((Financials!H57+Financials!H62)/365)*H17 -> 12861.806 | I16: =((Financials!I57+Financials!I62)/365)*I17 -> 13837.316 | J16: =((Financials!J57+Financials!J62)/365)*J17 -> 14887.324 | K16: =((Financials!K57+Financials!K62)/365)*K17 -> 16017.552 | L16: =((Financials!L57+Financials!L62)/365)*L17 -> 17234.168
A17: Days costs in A/P | C17: =Ratios!C81 -> 31.683937 | D17: =Ratios!D81 -> 36.386492 | E17: =Ratios!E81 -> 34.720015 | F17: =Ratios!F81 -> 30.552503 | G17: =Ratios!G81 -> 29.71707 | H17: 32.61 | I17: 32.61 | J17: 32.61 | K17: 32.61 | L17: 32.61
A18: 5 year average | G18: =AVERAGE(C17:G17) -> 32.612003
A20: Accrued salaries and related expenses | B20: =Financials!B23 -> 1494 | C20: =Financials!C23 -> 2463 | D20: =Financials!D23 -> 2426 | E20: =Financials!E23 -> 1991 | F20: =Financials!F23 -> 2096 | G20: =Financials!G23 -> 2315 | H20: =(Financials!H57+Financials!H62)*H21 -> 2591.293 | I20: =(Financials!I57+Financials!I62)*I21 -> 2787.831 | J20: =(Financials!J57+Financials!J62)*J21 -> 2999.378 | K20: =(Financials!K57+Financials!K62)*K21 -> 3227.0873 | L20: =(Financials!L57+Financials!L62)*L21 -> 3472.2013
A21: Percentage of COGS and SG&A | B21: =B20/(Financials!B57+Financials!B62) -> 0.016170056 | C21: =C20/(Financials!C57+Financials!C62) -> 0.022049345 | D21: =D20/(Financials!D57+Financials!D62) -> 0.019295162 | E21: =E20/(Financials!E57+Financials!E62) -> 0.015209038 | F21: =F20/(Financials!F57+Financials!F62) -> 0.01633582 | G21: =G20/(Financials!G57+Financials!G62) -> 0.017153993 | H21: 0.018 | I21: 0.018 | J21: 0.018 | K21: 0.018 | L21: 0.018
A22: 5 year average | G22: =AVERAGE(C21:G21) -> 0.018008672
A24: Sales taxes payable | B24: =Financials!B24 -> 605 | C24: =Financials!C24 -> 774 | D24: =Financials!D24 -> 848 | E24: =Financials!E24 -> 528 | F24: =Financials!F24 -> 449 | G24: =Financials!G24 -> 628 | H24: =Financials!H55*'Working Capital'!H25 -> 737.90809 | I24: =Financials!I55*'Working Capital'!I25 -> 793.87513 | J24: =Financials!J55*'Working Capital'!J25 -> 854.11619 | K24: =Financials!K55*'Working Capital'!K25 -> 918.9597 | L24: =Financials!L55*'Working Capital'!L25 -> 988.75947
A25: Percentage of revenue | B25: =B24/Financials!B55 -> 0.005488773 | C25: =C24/Financials!C55 -> 0.0058587541 | D25: =D24/Financials!D55 -> 0.0056100611 | E25: =E24/Financials!E55 -> 0.0033544469 | F25: =F24/Financials!F55 -> 0.0029410031 | G25: =G24/Financials!G55 -> 0.0039369585 | H25: 0.0043 | I25: 0.0043 | J25: 0.0043 | K25: 0.0043 | L25: 0.0043
A26: 5 year average | G26: =AVERAGE(C25:G25) -> 0.0043402447
A28: Deferred revenue | B28: =Financials!B25 -> 2116 | C28: =Financials!C25 -> 2823 | D28: =Financials!D25 -> 3596 | E28: =Financials!E25 -> 3064 | F28: =Financials!F25 -> 2762 | G28: =Financials!G25 -> 2610 | H28: =Financials!H55*'Working Capital'!H29 -> 3397.8094 | I28: =Financials!I55*'Working Capital'!I29 -> 3655.518 | J28: =Financials!J55*'Working Capital'!J29 -> 3932.9071 | K28: =Financials!K55*'Working Capital'!K29 -> 4231.4889 | L28: =Financials!L55*'Working Capital'!L29 -> 4552.8924
A29: Percentage of revenue | B29: =B28/Financials!B55 -> 0.019197097 | C29: =C28/Financials!C55 -> 0.021368557 | D29: =D28/Financials!D55 -> 0.023789834 | E29: =E28/Financials!E55 -> 0.019465957 | F29: =F28/Financials!F55 -> 0.018091427 | G29: =G28/Financials!G55 -> 0.0163622 | H29: 0.0198 | I29: 0.0198 | J29: 0.0198 | K29: 0.0198 | L29: 0.0198
A30: 5 year average | G30: =AVERAGE(C29:G29) -> 0.019815595
A32: Income taxes payable | B32: =Financials!B26 -> 55 | C32: =Financials!C26 -> 193 | D32: =Financials!D26 -> 158 | E32: =Financials!E26 -> 50 | F32: =Financials!F26 -> 28 | G32: =Financials!G26 -> 832 | H32: =Financials!H77*'Working Capital'!H33 -> 289.79899 | I32: =Financials!I77*'Working Capital'!I33 -> 316.50851 | J32: =Financials!J77*'Working Capital'!J33 -> 345.84095 | K32: =Financials!K77*'Working Capital'!K33 -> 374.17873 | L32: =Financials!L77*'Working Capital'!L33 -> 402.00635
A33: Percentage of tax expense | B33: =B32/Financials!B77 -> 0.015836453 | C33: =C32/Financials!C77 -> 0.046935798 | D33: =D32/Financials!D77 -> 0.029788839 | E33: =E32/Financials!E77 -> 0.0093075205 | F33: =F32/Financials!F77 -> 0.0058565154 | G33: =G32/Financials!G77 -> 0.18086957 | H33: 0.0546 | I33: 0.0546 | J33: 0.0546 | K33: 0.0546 | L33: 0.0546
A34: 5 year average | G34: =AVERAGE(C33:G33) -> 0.054551647
A36: Other accrued expenses | B36: =Financials!B29 -> 2677 | C36: =Financials!C29 -> 3063 | D36: =Financials!D29 -> 3891 | E36: =Financials!E29 -> 3858 | F36: =Financials!F29 -> 4225 | G36: =Financials!G29 -> 4166 | H36: =Financials!H55*'Working Capital'!H37 -> 4358.8059 | I36: =Financials!I55*'Working Capital'!I37 -> 4689.4019 | J36: =Financials!J55*'Working Capital'!J37 -> 5045.2445 | K36: =Financials!K55*'Working Capital'!K37 -> 5428.2736 | L36: =Financials!L55*'Working Capital'!L37 -> 5840.5792
A37: Percentage of revenue | B37: =B36/Financials!B55 -> 0.024286686 | C37: =C36/Financials!C55 -> 0.023185224 | D37: =D36/Financials!D55 -> 0.025741448 | E37: =E36/Financials!E55 -> 0.024510333 | F37: =F36/Financials!F55 -> 0.02767425 | G37: =G36/Financials!G55 -> 0.02611683 | H37: 0.0254 | I37: 0.0254 | J37: 0.0254 | K37: 0.0254 | L37: 0.0254
A38: 5 year average | G38: =AVERAGE(C37:G37) -> 0.025445617

Sheet Long Term Asset & Liab
A1: The Home Depot, Inc. | B1: ACTUAL | H1: FORECAST
A2: (in millions) | B2: 43863 | C2: 44227 | D2: 44591 | E2: 44955 | F2: 45319 | G2: 45690 | H2: 46053 | I2: 46418 | J2: 46783 | K2: 47149 | L2: 47514
A4: Property, plant and equipment (PP&E), net
A5: Land | B5: 8390 | C5: 8543 | D5: 8617 | E5: 8719 | F5: 9027 | G5: 9060
A6: Buildings | B6: 18432 | C6: 18838 | D6: 19173 | E6: 19430 | F6: 20030 | G6: 20260
A7: Furniture, fixtures, and equipment | B7: 13666 | C7: 15119 | D7: 16441 | E7: 16564 | F7: 16667 | G7: 18474
A8: Leasehold improvements | B8: 1789 | C8: 1925 | D8: 2016 | E8: 2130 | F8: 2254 | G8: 2423
A9: Construction in progress | B9: 1005 | C9: 1068 | D9: 1139 | E9: 1297 | F9: 1192 | G9: 1521
A10: Finance leases | B10: 1578 | C10: 3308 | D10: 3943 | E10: 4135 | F10: 4087 | G10: 4045
A11: Gross PP&E | B11: =SUM(B5:B10) -> 44860 | C11: =SUM(C5:C10) -> 48801 | D11: =SUM(D5:D10) -> 51329 | E11: =SUM(E5:E10) -> 52275 | F11: =SUM(F5:F10) -> 53257 | G11: =SUM(G5:G10) -> 55783 | H11: =G11+H19+H20+H21+H22+H23 -> 59376.303 | I11: =H11+I19+I20+I21+I22+I23 -> 63242.272 | J11: =I11+J19+J20+J21+J22+J23 -> 67402.217 | K11: =J11+K19+K20+K21+K22+K23 -> 71879.175 | L11: =K11+L19+L20+L21+L22+L23 -> 76698.05
A13: Accumulated depreciation | B13: 22090 | C13: 24096 | D13: 26130 | E13: 26644 | F13: 27103 | G13: 29081 | H13: =G13-H24 -> 32180.056 | I13: =H13-I24 -> 35478.739 | J13: =I13-J24 -> 38992.199 | K13: =J13-K24 -> 42736.766 | L13: =K13-L24 -> 46730.054
A15: Net PP&E | B15: =B11-B13 -> 22770 | C15: =C11-C13 -> 24705 | D15: =D11-D13 -> 25199 | E15: =E11-E13 -> 25631 | F15: =F11-F13 -> 26154 | G15: =G11-G13 -> 26702 | H15: =H11-H13 -> 27196.248 | I15: =I11-I13 -> 27763.533 | ... L15: =L11-L13 -> 29967.996
A18: Beginning Balance | C18: 22770 | D18: =C26 -> 24705 | E18: =D26 -> 25199 | F18: =E26 -> 25631 | G18: =F26 -> 26154 | H18: =G26 -> 26702 | I18: =H26 -> 27196.248 | J18: =I26 -> 27763.533 | K18: =J26 -> 28410.019 | L18: =K26 -> 29142.409
A19: Additions--capital expenditures | C19: =-Financials!C110 -> 2463 | D19: =-Financials!D110 -> 2566 | E19: =-Financials!E110 -> 3119 | F19: =-Financials!F110 -> 3226 | G19: =-Financials!G110 -> 3485 | H19: =AVERAGE(H52,H64,H87) -> 3599.3031 | I19: =AVERAGE(I52,I64,I87) -> 3871.9685 | J19: =AVERAGE(J52,J64,J87) -> 4165.9455 | K19: =AVERAGE(K52,K64,K87) -> 4482.9583 | L19: =AVERAGE(L52,L64,L87) -> 4824.8747
A20: Additions--mergers & acquisitions
A21: Additions--new finance leases | C21: =C10-B10 -> 1730 | D21: 672 | E21: 322 | F21: 336 | G21: 153 | H21: 0 | I21: 0 | J21: 0 | K21: 0 | L21: 0
A22: Impairments | C22: 0 | D22: 0 | E22: 0 | F22: 0 | G22: 0 | H22: 0 | I22: 0 | J22: 0 | K22: 0 | L22: 0
A23: Disposals | C23: =IF(C31>0,-C31,0) -> 0 | D23: =IF(D31>0,-D31,0) -> 0 | E23: =IF(E31>0,-E31,0) -> 0 | F23: =IF(F31>0,-F31,0) -> 0 | G23: =IF(G31>0,-G31,0) -> 0 | H23: =IF(H31>0,-H31,0) -> -6 | I23: =IF(I31>0,-I31,0) -> -6 | J23: =IF(J31>0,-J31,0) -> -6 | ... L23: =IF(L31>0,-L31,0) -> -6
A24: Depreciation | C24: -2425 | D24: =-2650 -> -2650 | E24: =-Financials!E89 -> -2796 | F24: =-Financials!F89 -> -3061 | G24: =-Financials!G89 -> -3336 | H24: =-G11/H40 -> -3099.0556 | I24: =-H11/I40 -> -3298.6835 | J24: =-I11/J40 -> -3513.4595 | K24: =-J11/K40 -> -3744.5676 | L24: =-K11/L40 -> -3993.2875
A25: Unknown | C25: 167 | D25: -94 | E25: -213 | F25: 22 | G25: 246
A26: Ending Balance | C26: =SUM(C18:C25) -> 24705 | D26: =SUM(D18:D25) -> 25199 | E26: =SUM(E18:E25) -> 25631 | F26: =SUM(F18:F25) -> 26154 | G26: =SUM(G18:G25) -> 26702 | H26: =SUM(H18:H25) -> 27196.248 | I26: =SUM(I18:I25) -> 27763.533 | J26: =SUM(J18:J25) -> 28410.019 | ... L26: =SUM(L18:L25) -> 29967.996
A29: SALE/DISPOSAL OF PP&E
A30: Cash received | B30: =Financials!B112 -> 37 | C30: =Financials!C112 -> 0 | D30: =Financials!D112 -> 0 | E30: =Financials!E112 -> 0 | F30: =Financials!F112 -> 0 | G30: =Financials!G112 -> 0 | H30: 6 | I30: 6 | J30: 6 | K30: 6 | L30: 6
A31: Net PP&E | B31: =B30-B32 -> 37 | C31: =C30-C32 -> 0 | D31: =D30-D32 -> 0 | E31: =E30-E32 -> 0 | F31: =F30-F32 -> 0 | G31: =G30-G32 -> 0 | H31: =H30-H32 -> 6 | I31: =I30-I32 -> 6 | ... L31: =L30-L32 -> 6
A32: Gain (loss) | B32: 0 | C32: 0 | D32: 0 | E32: 0 | F32: 0 | G32: 0 | H32: 0 | I32: 0 | J32: 0 | K32: 0 | L32: 0
A34: Average Cash | G34: =AVERAGE(B30:G30) -> 6.1666667
A35: Average Gain | G35: =AVERAGE(B32:F32) -> 0
A38: FORECAST DEPRECIATION EXPENSE
A40: Average Useful Life | C40: =AVERAGE(B11:C11)/-C24 -> 19.311546 | D40: =AVERAGE(C11:D11)/-D24 -> 18.892453 | E40: =AVERAGE(D11:E11)/-E24 -> 18.527182 | F40: =AVERAGE(E11:F11)/-F24 -> 17.238157 | G40: =AVERAGE(F11:G11)/-G24 -> 16.342926 | H40: 18 | I40: 18 | J40: 18 | K40: 18 | L40: 18
A41: 5 year average | G41: =AVERAGE(C40:G40) -> 18.062453
A44: Depreciation on income statement | C44: =Financials!C63 -> 2128 | D44: =Financials!D63 -> 2386 | E44: =Financials!E63 -> 2455 | F44: =Financials!F63 -> 2673 | G44: =Financials!G63 -> 3034 | H44: =H45*H46 -> 2758.1594 | I44: =I45*I46 -> 2935.8283 | J44: =J45*J46 -> 3126.979 | K44: =K45*K46 -> 3332.6652 | L44: =L45*L46 -> 3554.0259
A45: Total depreciation expense | C45: =-C24 -> 2425 | D45: =-D24 -> 2650 | E45: =-E24 -> 2796 | F45: =-F24 -> 3061 | G45: =-G24 -> 3336 | H45: =-H24 -> 3099.0556 | I45: =-I24 -> 3298.6835 | J45: =-J24 -> 3513.4595 | ... L45: =-L24 -> 3993.2875
A46: Ratio | C46: =C44/C45 -> 0.87752577 | D46: =D44/D45 -> 0.90037736 | E46: =E44/E45 -> 0.87804006 | F46: =F44/F45 -> 0.87324404 | G46: =G44/G45 -> 0.90947242 | H46: 0.89 | I46: 0.89 | J46: 0.89 | K46: 0.89 | L46: 0.89
A50: FORECAST CAPITAL EXPENDITURES METHOD 1--LINK TO COMPANY OWNED STORES
A52: Capital expenditures | C52: =C19 -> 2463 | D52: =D19 -> 2566 | E52: =E19 -> 3119 | F52: =F19 -> 3226 | G52: =G19 -> 3485 | H52: =H54*H57 -> 3806.9353 | I52: =I54*I57 -> 4158.6249 | J52: =J54*J57 -> 4542.8202 | K52: =K54*K57 -> 4962.5272 | L52: =L54*L57 -> 5421.0299
A54: Number of company operated stores: | C54: =Revenue!C53 -> 2296 | D54: =Revenue!D53 -> 2317 | E54: =Revenue!E53 -> 2322 | F54: =Revenue!F53 -> 2335 | G54: =Revenue!G53 -> 2347 | H54: =Revenue!H53 -> 2358.3937 | I54: =Revenue!I53 -> 2369.8511 | J54: =Revenue!J53 -> 2381.3727 | ... L54: =Revenue!L53 -> 2404.6099
A56: Capital expenditures per company store
A57: Average | C57: =C52/C54 -> 1.0727352 | D57: =D52/D54 -> 1.1074666 | E57: =E52/E54 -> 1.3432386 | F57: =F52/F54 -> 1.3815846 | G57: =G52/G54 -> 1.4848743 | H57: =G57*(1+H58) -> 1.6142069 | I57: =H57*(1+I58) -> 1.7548043 | J57: =I57*(1+J58) -> 1.9076477 | K57: =J57*(1+K58) -> 2.0738038 | L57: =K57*(1+L58) -> 2.2544322
A58: % change | D58: =(D57-C57)/C57 -> 0.032376452 | E58: =(E57-D57)/D57 -> 0.21289314 | F58: =(F57-E57)/E57 -> 0.028547419 | G58: =(G57-F57)/F57 -> 0.074761782 | H58: 0.0871 | I58: 0.0871 | J58: 0.0871 | K58: 0.0871 | L58: 0.0871
A62: FORECAST CAPITAL EXPENDITURES METHOD 2--AS A % REVENUE
...

Sheet Financing
A1: The Home Depot, Inc. | B1: ACTUAL | H1: FORECAST
A2: (in millions) | B2: 43863 | C2: 44227 | D2: 44591 | E2: 44955 | F2: 45319 | G2: 45690 | H2: 46053 | I2: 46418 | J2: 46783 | K2: 47149 | L2: 47514
A4: Current maturities long-term debt--actual | B4: =Financials!B27 -> 1839 | C4: =Financials!C27 -> 1416 | D4: =Financials!D27 -> 2447 | E4: =Financials!E27 -> 1231 | F4: =Financials!F27 -> 1368 | G4: =Financials!G27 -> 4582
A6: Beginning Balance | C6: =B9 -> 1839 | D6: =C9 -> 1416 | E6: =D9 -> 2447 | F6: =E9 -> 1231 | G6: =F9 -> 1368 | H6: =G9 -> 4582 | I6: =H9 -> 4845 | J6: =I9 -> 3769 | ... L6: =K9 -> 3946
A7: Payments | C7: =-C6 -> -1839 | D7: =-D6 -> -1416 | E7: =-E6 -> -2447 | F7: =-F6 -> -1231 | G7: =-G6 -> -1368 | H7: =-H6 -> -4582 | I7: =-I6 -> -4845 | J7: =-J6 -> -3769 | ... L7: =-L6 -> -3946
A8: Transfer from Long-term | C8: =C4 -> 1416 | D8: =D4 -> 2447 | E8: =E4 -> 1231 | F8: =F4 -> 1368 | G8: =G4 -> 4582 | H8: =-I24 -> 4845 | I8: =-J24 -> 3769 | J8: =-K24 -> 2727 | K8: =-L24 -> 3946 | L8: =-M24 -> 3946
A9: Ending Balance | B9: =B4 -> 1839 | C9: =SUM(C6:C8) -> 1416 | D9: =SUM(D6:D8) -> 2447 | E9: =SUM(E6:E8) -> 1231 | F9: =SUM(F6:F8) -> 1368 | G9: =SUM(G6:G8) -> 4582 | H9: =SUM(H6:H8) -> 4845 | I9: =SUM(I6:I8) -> 3769 | J9: =SUM(J6:J8) -> 2727 | ... L9: =SUM(L6:L8) -> 3946
A12: Long-term debt--balance sheet--actual | B12: =Financials!B32 -> 28670 | C12: =Financials!C32 -> 35822 | D12: =Financials!D32 -> 36604 | E12: =Financials!E32 -> 41962 | F12: =Financials!F32 -> 42743 | G12: =Financials!G32 -> 48485
A14: Beginning Balance | C14: =B21 -> 28670 | D14: =C21 -> 35822 | E14: =D21 -> 36604 | F14: =E21 -> 41962 | G14: =F21 -> 42743 | H14: =G21 -> 48485 | I14: =H21 -> 43640 | J14: =I21 -> 39871 | ... L14: =K21 -> 33198
A15: Payments | C15: =C25 -> -1033 | D15: =D25 -> -116 | E15: =E25 -> -44 | F15: =F25 -> -40 | G15: =G25 -> -168
A16: Transfer to short-term | C16: =-C8 -> -1416 | D16: =-D8 -> -2447 | E16: =-E8 -> -1231 | F16: =-F8 -> -1368 | G16: =-G8 -> -4582 | H16: =-H8 -> -4845 | I16: =-I8 -> -3769 | J16: =-J8 -> -2727 | ... L16: =-L8 -> -3946
A17: Additions--new debt | C17: =Financials!C120 -> 7933 | D17: =Financials!D120 -> 2979 | E17: =Financials!E120 -> 6942 | F17: =Financials!F120 -> 1995 | G17: =Financials!G120 -> 10010
A18: Debt incurred in acquisitions
A19: New finance leases | C19: ='Long Term Asset & Liab'!C21 -> 1730 | D19: ='Long Term Asset & Liab'!D21 -> 672 | E19: ='Long Term Asset & Liab'!E21 -> 322 | F19: ='Long Term Asset & Liab'!F21 -> 336 | G19: ='Long Term Asset & Liab'!G21 -> 153
A20: Unknown | C20: -62 | D20: -306 | E20: -631 | F20: -142 | G20: 329
A21: Ending Balance | B21: =B12 -> 28670 | C21: =SUM(C14:C20) -> 35822 | D21: =SUM(D14:D20) -> 36604 | E21: =SUM(E14:E20) -> 41962 | F21: =SUM(F14:F20) -> 42743 | G21: =SUM(G14:G20) -> 48485 | H21: =SUM(H14:H20) -> 43640 | I21: =SUM(I14:I20) -> 39871 | J21: =SUM(J14:J20) -> 37144 | ... L21: =SUM(L14:L20) -> 29252
A24: Minimum Debt Payments | C24: =C7 -> -1839 | D24: =D7 -> -1416 | E24: =E7 -> -2447 | F24: =F7 -> -1231 | G24: =G7 -> -1368 | H24: -4582 | I24: =-4608-237 -> -4845 | J24: =-3559-210 -> -3769 | K24: =-2554-173 -> -2727 | L24: =-3799-147 -> -3946 | M24: =L24 -> -3946
A25: Additional Payments--if have extra cash | C25: =C26-C24 -> -1033 | D25: =D26-D24 -> -116 | E25: =E26-E24 -> -44 | F25: =F26-F24 -> -40 | G25: =G26-G24 -> -168
A26: Total Debt Payments | C26: =Financials!C121 -> -2872 | D26: =Financials!D121 -> -1532 | E26: =Financials!E121 -> -2491 | F26: =Financials!F121 -> -1271 | G26: =Financials!G121 -> -1536 | H26: =H24+H25 -> -4582 | I26: =I24+I25 -> -4845 | J26: =J24+J25 -> -3769 | K26: =K24+K25 -> -2727 | L26: =L24+L25 -> -3946
A29: Interest Expense | C29: =Financials!C71 -> 1347 | D29: =Financials!D71 -> 1347 | E29: =Financials!E71 -> 1617 | F29: =Financials!F71 -> 1943 | G29: =Financials!G71 -> 2321 | H29: =(G9+G21)*H31 -> 2191.6671 | I29: =(H9+H21)*I31 -> 2002.4305 | J29: =(I9+I21)*J31 -> 1802.332 | K29: =(J9+J21)*K31 -> 1646.6723 | L29: =(K9+K21)*L31 -> 1534.0472
A31: Interest Rate (interest expense/average debt) | C31: =C29/((B9+C9+B21+C21)/2) -> 0.039765598 | D31: =D29/((C9+D9+C21+D21)/2) -> 0.035313086 | E31: =E29/((D9+E9+D21+E21)/2) -> 0.039322017 | F31: =F29/((E9+F9+E21+F21)/2) -> 0.044511134 | G31: =G29/((F9+G9+F21+G21)/2) -> 0.047768013 | H31: 0.0413 | I31: 0.0413 | J31: 0.0413 | K31: 0.0413 | L31: 0.0413
A47: Owners Equity
A49: Common stock | B49: =Financials!B39 -> 89 | C49: =Financials!C39 -> 89 | D49: =Financials!D39 -> 90 | E49: =Financials!E39 -> 90 | F49: =Financials!F39 -> 90 | G49: =Financials!G39 -> 90 | H49: =G49 -> 90 | I49: =H49 -> 90 | J49: =I49 -> 90 | K49: =J49 -> 90 | L49: =K49 -> 90
A50: Additional paid in capital | B50: =Financials!B40 -> 11001 | C50: =Financials!C40 -> 11540 | D50: =Financials!D40 -> 12132 | E50: =Financials!E40 -> 12592 | F50: =Financials!F40 -> 13147 | G50: =Financials!G40 -> 14117 | H50: =H51-H49 -> 14811.189 | I50: =I51-I49 -> 15560.124 | J50: =J51-J49 -> 16368.218 | K50: =K51-K49 -> 17240.231 | L50: =L51-L49 -> 18181.727
A51: Total common equity | B51: =B49+B50 -> 11090 | C51: =C49+C50 -> 11629 | D51: =D49+D50 -> 12222 | E51: =E49+E50 -> 12682 | F51: =F49+F50 -> 13237 | G51: =G49+G50 -> 14207 | H51: =H57 -> 14901.189 | I51: =I57 -> 15650.124 | J51: =J57 -> 16458.218 | K51: =K57 -> 17330.231 | L51: =L57 -> 18271.727
A53: Beginning balance | C53: =B51 -> 11090 | D53: =C57 -> 11629 | E53: =D57 -> 12222 | F53: =E57 -> 12682 | G53: =F57 -> 13237 | H53: =G57 -> 14207 | I53: =H57 -> 14901.189 | J53: =I57 -> 15650.124 | K53: =J57 -> 16458.218 | L53: =K57 -> 17330.231
A54: Issue new stock
A55: Share-based compensation--issue stock | C55: 229 | D55: =1+194 -> 195 | E55: 94 | F55: 175 | G55: 528 | H55: =H64*H56 -> 268.33214 | I55: =I64*I56 -> 289.49404 | J55: =J64*J56 -> 312.36118 | K55: =K64*K56 -> 337.06864 | L55: =L64*L56 -> 363.92644
A56: Share-based compensation--expense | C56: 310 | D56: 398 | E56: 366 | F56: 380 | G56: 442 | H56: =Financials!H67*H61 -> 425.85643 | I56: =Financials!I67*I61 -> 459.44143 | J56: =Financials!J67*J61 -> 495.73271 | K56: =Financials!K67*K61 -> 534.94467 | L56: =Financials!L67*L61 -> 577.56935
A57: Ending balance | C57: =SUM(C53:C56) -> 11629 | D57: =SUM(D53:D56) -> 12222 | E57: =SUM(E53:E56) -> 12682 | F57: =SUM(F53:F56) -> 13237 | G57: =SUM(G53:G56) -> 14207 | H57: =SUM(H53:H56) -> 14901.189 | I57: =SUM(I53:I56) -> 15650.124 | J57: =SUM(J53:J56) -> 16458.218 | ... L57: =SUM(L53:L56) -> 18271.727
A60: Stock compensation
A61: Compensation Expense as a % operating income | C61: =C56/Financials!E67 -> 0.012895711 | D61: =D56/Financials!F67 -> 0.018350316 | E61: =E56/Financials!G67 -> 0.017002694 | F61: =F56/Financials!H67 -> 0.015615591 | G61: =G56/Financials!I67 -> 0.016835661 | H61: 0.0175 | I61: 0.0175 | J61: 0.0175 | K61: 0.0175 | L61: 0.0175
A62: average | G62: =AVERAGE(C61:G61) -> 0.016139995
A64: Stock issuance as a % compensation expense | C64: =C55/C56 -> 0.73870968 | D64: =D55/D56 -> 0.48994975 | E64: =E55/E56 -> 0.2568306 | F64: =F55/F56 -> 0.46052632 | G64: =G55/G56 -> 1.1945701 | H64: 0.6301 | I64: 0.6301 | J64: 0.6301 | K64: 0.6301 | L64: 0.6301
A65: average | G65: =AVERAGE(C64:G64) -> 0.6281173
A68: Shares issued | C68: =C89 -> 3 | D68: =D89 -> 3 | E68: =E89 -> 2 | F68: =F89 -> 2 | G68: =G89 -> 4 | H68: =G73*H75 -> 2.4001644 | I68: =H73*I75 -> 2.74984 | J68: =I73*J75 -> 2.74984 | K68: =J73*K75 -> 2.74984 | L68: =K73*L75 -> 2.74984
A70: Shares Available
A71: Stock options outstanding | B71: 5.212 | C71: 4.35 | D71: 3.641 | E71: 3.626 | F71: 3.085 | G71: 2.201 | H71: 3.6 | I71: 3.6 | J71: 3.6 | K71: 3.6 | L71: 3.6
A72: Nonvested restricted & performance stock | B72: 3.975 | C72: 4.098 | D72: 3.709 | E72: 3.359 | F72: 3.386 | G72: =3.05+1.208 -> 4.258 | H72: 3.8 | I72: 3.8 | J72: 3.8 | K72: 3.8 | L72: 3.8
B73: =SUM(B71:B72) -> 9.187 | C73: =SUM(C71:C72) -> 8.448 | D73: =SUM(D71:D72) -> 7.35 | E73: =SUM(E71:E72) -> 6.985 | F73: =SUM(F71:F72) -> 6.471 | G73: =SUM(G71:G72) -> 6.459 | H73: =SUM(H71:H72) -> 7.4 | I73: =SUM(I71:I72) -> 7.4 | ... L73: =SUM(L71:L72) -> 7.4
...

Sheet Free Cash Flows
A1: The Home Depot, Inc. | B1: ACTUAL | H1: FORECAST
A2: (in millions) | B2: 43863 | C2: 44227 | D2: 44591 | E2: 44955 | F2: 45319 | G2: 45690 | H2: 46053 | I2: 46418 | J2: 46783 | K2: 47149 | L2: 47514
A4: Earnings before Interest and Taxes | H4: =Financials!H75-Financials!H73 -> 19951.319 | I4: =Financials!I75-Financials!I73 -> 22113.824 | J4: =Financials!J75-Financials!J73 -> 24522.507 | K4: =Financials!K75-Financials!K73 -> 26612.295 | L4: =Financials!L75-Financials!L73 -> 28429.109
A5: Tax Rate | H5: =Expenses!H22 -> 0.2397 | I5: =Expenses!I22 -> 0.2397 | J5: =Expenses!J22 -> 0.2397 | K5: =Expenses!K22 -> 0.2397 | L5: =Expenses!L22 -> 0.2397
A6: Less Taxes | H6: =H4*H5 -> 4782.3311 | I6: =I4*I5 -> 5300.6835 | J6: =J4*J5 -> 5878.045 | K6: =K4*K5 -> 6378.9672 | L6: =L4*L5 -> 6814.4574
A7: Earnings After Tax | H7: =H4-H6 -> 15168.988 | I7: =I4-I6 -> 16813.14 | J7: =J4-J6 -> 18644.462 | K7: =K4-K6 -> 20233.328 | L7: =L4-L6 -> 21614.651
A9: Less Capital Expenditures (Net) | H9: =Financials!H110+Financials!H112 -> -3593.3031 | I9: =Financials!I110+Financials!I112 -> -3865.9685 | J9: =Financials!J110+Financials!J112 -> -4159.9455 | K9: =Financials!K110+Financials!K112 -> -4476.9583 | L9: =Financials!L110+Financials!L112 -> -4818.8747
A11: Add Depreciation and amortization | H11: =Financials!H89+Financials!H90 -> 3652.0556 | I11: =Financials!I89+Financials!I90 -> 3851.6835 | J11: =Financials!J89+Financials!J90 -> 4058.4595 | K11: =Financials!K89+Financials!K90 -> 4272.5676 | L11: =Financials!L89+Financials!L90 -> 4479.2875
A13: Add Other Non-cash Items | H13: ='Long Term Asset & Liab'!H32 -> 0 | I13: ='Long Term Asset & Liab'!I32 -> 0 | J13: ='Long Term Asset & Liab'!J32 -> 0 | K13: ='Long Term Asset & Liab'!K32 -> 0 | L13: ='Long Term Asset & Liab'!L32 -> 0
A15: Change in Working Capital Requirements | H15: =SUM(Financials!H94:H105) -> 2624.4056 | I15: =SUM(Financials!I94:I105) -> -182.23753 | J15: =SUM(Financials!J94:J105) -> -193.10849 | K15: =SUM(Financials!K94:K105) -> -208.37644 | L15: =SUM(Financials!L94:L105) -> -223.55984
A17: Free Cash Flows | H17: =SUM(H7:H15) -> 17852.146 | I17: =SUM(I7:I15) -> 16616.618 | J17: =SUM(J7:J15) -> 18349.868 | K17: =SUM(K7:K15) -> 19820.561 | L17: =SUM(L7:L15) -> 21051.504

Sheet Ratios
A1: The Home Depot, Inc. | B1: ACTUAL | H1: FORECAST
A2: (in millions) | B2: 43863 | C2: 44227 | D2: 44591 | E2: 44955 | F2: 45319 | G2: 45690 | H2: 46053 | I2: 46418 | J2: 46783 | K2: 47149 | L2: 47514
A4: LIQUIDITY RATIOS
A6: Current Ratio
A7: Current Assets | B7: =Financials!B10 -> 19810 | C7: =Financials!C10 -> 28477 | D7: =Financials!D10 -> 29055 | E7: =Financials!E10 -> 32471 | F7: =Financials!F10 -> 29775 | G7: =Financials!G10 -> 31683 | H7: =Financials!H10 -> 32194.983 | I7: =Financials!I10 -> 34832.868 | ... L7: =Financials!L10 -> 58165.403
A8: Current Liabilities | B8: =Financials!B30 -> 18375 | C8: =Financials!C30 -> 23166 | D8: =Financials!D30 -> 28693 | E8: =Financials!E30 -> 23110 | F8: =Financials!F30 -> 22015 | G8: =Financials!G30 -> 28661 | H8: =Financials!H30 -> 30672.421 | I8: =Financials!I30 -> 31439.451 | ... L8: =Financials!L30 -> 38026.607
A10: Current ratio | B10: =B7/B8 -> 1.0780952 | C10: =C7/C8 -> 1.2292584 | D10: =D7/D8 -> 1.0126163 | E10: =E7/E8 -> 1.4050627 | F10: =F7/F8 -> 1.3524869 | G10: =G7/G8 -> 1.1054394 | H10: =H7/H8 -> 1.0496394 | I10: =I7/I8 -> 1.107935 | ... L10: =L7/L8 -> 1.5295975
A13: Quick Ratio (acid test)
A14: Cash + ST Investments + Acct. Rec. | B14: =Financials!B5+Financials!B6+Financials!B7 -> 4239 | C14: =Financials!C5+Financials!C6+Financials!C7 -> 10887 | D14: =Financials!D5+Financials!D6+Financials!D7 -> 5769 | E14: =Financials!E5+Financials!E6+Financials!E7 -> 6074 | F14: =Financials!F5+Financials!F6+Financials!F7 -> 7088 | G14: =Financials!G5+Financials!G6+Financials!G7 -> 6562 | H14: =Financials!H5+Financials!H6+Financials!H7 -> 7321.6164 | I14: =Financials!I5+Financials!I6+Financials!I7 -> 8072.9676 | ... L14: =Financials!L5+Financials!L6+Financials!L7 -> 24836.351
A15: Total Current Liabilities | B15: =Financials!B30 -> 18375 | C15: =Financials!C30 -> 23166 | D15: =Financials!D30 -> 28693 | E15: =Financials!E30 -> 23110 | F15: =Financials!F30 -> 22015 | G15: =Financials!G30 -> 28661 | H15: =Financials!H30 -> 30672.421 | I15: =Financials!I30 -> 31439.451 | ... L15: =Financials!L30 -> 38026.607
A17: Quick ratio | B17: =B14/B15 -> 0.23069388 | C17: =C14/C15 -> 0.46995597 | D17: =D14/D15 -> 0.20105949 | E17: =E14/E15 -> 0.26282994 | F17: =F14/F15 -> 0.3219623 | G17: =G14/G15 -> 0.22895223 | H17: =H14/H15 -> 0.23870357 | I17: =I14/I15 -> 0.25677826 | ... L17: =L14/L15 -> 0.65313087
A21: DEBT (LEVERAGE) RATIOS
A23: Total Liabilities to Total Assets
A24: Total Liabilities | B24: =Financials!B36 -> 54352 | C24: =Financials!C36 -> 67282 | D24: =Financials!D36 -> 73572 | E24: =Financials!E36 -> 74883 | F24: =Financials!F36 -> 75486 | G24: =Financials!G36 -> 89479 | H24: =Financials!H36 -> 86215.539 | I24: =Financials!I36 -> 83418.323 | ... L24: =Financials!L36 -> 80116.493
A25: Total Assets | B25: =Financials!B17 -> 51236 | C25: =Financials!C17 -> 70581 | D25: =Financials!D17 -> 71876 | E25: =Financials!E17 -> 76445 | F25: =Financials!F17 -> 76530 | G25: =Financials!G17 -> 96119 | H25: =Financials!H17 -> 96660.46 | I25: =Financials!I17 -> 99371.2 | ... L25: =Financials!L17 -> 123553.15
A27: Total Liabilities to Total Assets | B27: =B24/B25 -> 1.0608166 | C27: =C24/C25 -> 0.95325938 | D27: =D24/D25 -> 1.0235962 | E27: =E24/E25 -> 0.97956701 | F27: =F24/F25 -> 0.98635829 | G27: =G24/G25 -> 0.93091897 | H27: =H24/H25 -> 0.89194216 | I27: =I24/I25 -> 0.83946176 | ... L27: =L24/L25 -> 0.64843749
A30: Debt to Debt + Equity
A31: Interest Bearing Debt | B31: =Financials!B21+Financials!B27+Financials!B32 -> 31483 | C31: =Financials!C21+Financials!C27+Financials!C32 -> 37238 | D31: =Financials!D21+Financials!D27+Financials!D32 -> 40086 | E31: =Financials!E21+Financials!E27+Financials!E32 -> 43193 | F31: =Financials!F21+Financials!F27+Financials!F32 -> 44111 | G31: =Financials!G21+Financials!G27+Financials!G32 -> 53383 | H31: =Financials!H21+Financials!H27+Financials!H32 -> 48801 | I31: =Financials!I21+Financials!I27+Financials!I32 -> 43956 | ... L31: =Financials!L21+Financials!L27+Financials!L32 -> 33514
A32: Int. Bearing Debt + Common Equity | B32: =Financials!B21+Financials!B27+Financials!B32+Financials!B44 -> 28367 | C32: =Financials!C21+Financials!C27+Financials!C32+Financials!C44 -> 40537 | D32: =Financials!D21+Financials!D27+Financials!D32+Financials!D44 -> 38390 | E32: =Financials!E21+Financials!E27+Financials!E32+Financials!E44 -> 44755 | F32: =Financials!F21+Financials!F27+Financials!F32+Financials!F44 -> 45155 | G32: =Financials!G21+Financials!G27+Financials!G32+Financials!G44 -> 60023 | H32: =Financials!H21+Financials!H27+Financials!H32+Financials!H44 -> 59245.921 | I32: =Financials!I21+Financials!I27+Financials!I32+Financials!I44 -> 59908.878 | ... L32: =Financials!L21+Financials!L27+Financials!L32+Financials!L44 -> 76950.654
A34: Debt to Debt + Equity | B34: =B31/B32 -> 1.1098459 | C34: =C31/C32 -> 0.91861756 | D34: =D31/D32 -> 1.0441782 | E34: =E31/E32 -> 0.96509887 | F34: =F31/F32 -> 0.97687964 | G34: =G31/G32 -> 0.88937574 | H34: =H31/H32 -> 0.82370228 | I34: =I31/I32 -> 0.73371429 | ... L34: =L31/L32 -> 0.43552586
A37: Times Interest Earned (interest coverage)
A38: Operating Income | B38: =Financials!B67 -> 15843 | C38: =Financials!C67 -> 18278 | D38: =Financials!D67 -> 23040 | E38: =Financials!E67 -> 24039 | F38: =Financials!F67 -> 21689 | G38: =Financials!G67 -> 21526 | H38: =Financials!H67 -> 24334.653 | I38: =Financials!I67 -> 26253.796 | ... L38: =Financials!L67 -> 33003.963
A39: Interest Expense | B39: =Financials!B71 -> 1201 | C39: =Financials!C71 -> 1347 | D39: =Financials!D71 -> 1347 | E39: =Financials!E71 -> 1617 | F39: =Financials!F71 -> 1943 | G39: =Financials!G71 -> 2321 | H39: =Financials!H71 -> 2191.6671 | I39: =Financials!I71 -> 2002.4305 | ... L39: =Financials!L71 -> 1534.0472
A41: Times Interest Earned | B41: =B38/B39 -> 13.191507 | C41: =C38/C39 -> 13.569414 | D41: =D38/D39 -> 17.104677 | E41: =E38/E39 -> 14.866419 | F41: =F38/F39 -> 11.162635 | G41: =G38/G39 -> 9.2744507 | H41: =H38/H39 -> 11.103262 | I41: =I38/I39 -> 13.110965 | ... L41: =L38/L39 -> 21.514307
A44: Debt to EBITDA
A45: Interest Bearing Debt | B45: =Financials!B21+Financials!B27+Financials!B32 -> 31483 | C45: =Financials!C21+Financials!C27+Financials!C32 -> 37238 | D45: =Financials!D21+Financials!D27+Financials!D32 -> 40086 | E45: =Financials!E21+Financials!E27+Financials!E32 -> 43193 | F45: =Financials!F21+Financials!F27+Financials!F32 -> 44111 | G45: =Financials!G21+Financials!G27+Financials!G32 -> 53383 | H45: =Financials!H21+Financials!H27+Financials!H32 -> 48801 | I45: =Financials!I21+Financials!I27+Financials!I32 -> 43956 | ... L45: =Financials!L21+Financials!L27+Financials!L32 -> 33514
A46: Earnings before Int. Tax. Depr. & Amort. | B46: =Financials!B75+Financials!B71+Financials!B89+Financials!B90 -> 18212 | C46: =Financials!C75+Financials!C71+Financials!C89+Financials!C90 -> 20844 | D46: =Financials!D75+Financials!D71+Financials!D89+Financials!D90 -> 25946 | E46: =Financials!E75+Financials!E71+Financials!E89+Financials!E90 -> 27069 | F46: =Financials!F75+Financials!F71+Financials!F89+Financials!F90 -> 25114 | G46: =Financials!G75+Financials!G71+Financials!G89+Financials!G90 -> 25488 | H46: =Financials!H75+Financials!H71+Financials!H89+Financials!H90 -> 27986.709 | I46: =Financials!I75+Financials!I71+Financials!I89+Financials!I90 -> 30037.924 | ... L46: =Financials!L75+Financials!L71+Financials!L89+Financials!L90 -> 36729.87
A48: Debt to EBITDA | B48: =B45/B46 -> 1.7286954 | C48: =C45/C46 -> 1.7865093 | D48: =D45/D46 -> 1.544978 | E48: =E45/E46 -> 1.5956629 | F48: =F45/F46 -> 1.7564307 | G48: =G45/G46 -> 2.0944366 | H48: =H45/H46 -> 1.7437206 | I48: =I45/I46 -> 1.4633501 | ... L48: =L45/L46 -> 0.91244536
A52: ASSET MANAGEMENT RATIOS
A54: Days Sales in A/R
A55: Average Accounts Receivable | C55: =(Financials!B7+Financials!C7)/2 -> 2549 | D55: =(Financials!C7+Financials!D7)/2 -> 3209 | E55: =(Financials!D7+Financials!E7)/2 -> 3371.5 | F55: =(Financials!E7+Financials!F7)/2 -> 3322.5 | G55: =(Financials!F7+Financials!G7)/2 -> 4115.5 | H55: =(Financials!G7+Financials!H7)/2 -> 4329.7688 | I55: =(Financials!H7+Financials!I7)/2 -> 3898.9958 | J55: =(Financials!I7+Financials!J7)/2 -> 4194.7915 | ... L55: =(Financials!K7+Financials!L7)/2 -> 4855.9019
A56: Sales | C56: =Financials!C55 -> 132110 | D56: =Financials!D55 -> 151157 | E56: =Financials!E55 -> 157403 | F56: =Financials!F55 -> 152669 | G56: =Financials!G55 -> 159514 | H56: =Financials!H55 -> 171606.53 | I56: =Financials!I55 -> 184622.12 | J56: =Financials!J55 -> 198631.67 | ... L56: =Financials!L55 -> 229944.06
A57: 365 days | C57: 365 | D57: 365 | E57: 365 | F57: 365 | G57: 365 | H57: 365 | I57: 365 | J57: 365 | K57: 365 | L57: 365
A59: Days Sales in A/R | C59: =C55/(C56/C57) -> 7.0425025 | D59: =D55/(D56/D57) -> 7.7487976 | E59: =E55/(E56/E57) -> 7.8181324 | F59: =F55/(F56/F57) -> 7.9434103 | G59: =G55/(G56/G57) -> 9.4170888 | H59: =H55/(H56/H57) -> 9.2092391 | I59: =I55/(I56/I57) -> 7.7083583 | J59: =J55/(J56/J57) -> 7.7082315 | ... L59: =L55/(L56/L57) -> 7.7079799
A62: Inventory Turnover
A63: Cost of Goods Sold | C63: =Financials!C57 -> 87257 | D63: =Financials!D57 -> 100325 | E63: =Financials!E57 -> 104625 | F63: =Financials!F57 -> 101709 | G63: =Financials!G57 -> 106206 | H63: =Financials!H57 -> 113826.61 | I63: =Financials!I57 -> 122459.85 | J63: =Financials!J57 -> 131752.39 | ... L63: =Financials!L57 -> 152521.9
A64: Average Inventory | C64: =(Financials!B8+Financials!C8)/2 -> 15579 | D64: =(Financials!C8+Financials!D8)/2 -> 19347.5 | E64: =(Financials!D8+Financials!E8)/2 -> 23477 | F64: =(Financials!E8+Financials!F8)/2 -> 22931 | G64: =(Financials!F8+Financials!G8)/2 -> 22213.5 | H64: =(Financials!G8+Financials!H8)/2 -> 23364.213 | I64: =(Financials!H8+Financials!I8)/2 -> 24160.171 | J64: =(Financials!I8+Financials!J8)/2 -> 25993.072 | ... L64: =(Financials!K8+Financials!L8)/2 -> 30089.65
A66: Inventory Turnover | C66: =C63/C64 -> 5.6009372 | D66: =D63/D64 -> 5.1854245 | E66: =E63/E64 -> 4.4564893 | F66: =F63/F64 -> 4.4354367 | G66: =G63/G64 -> 4.7811466 | H66: =H63/H64 -> 4.871836 | I66: =I63/I64 -> 5.0686668 | J66: =J63/J64 -> 5.0687502 | ... L66: =L63/L64 -> 5.0689157
A69: Age of Inventory
A70: 365 | C70: 365 | D70: 365 | E70: 365 | F70: 365 | G70: 365 | H70: 365 | I70: 365 | J70: 365 | K70: 365 | L70: 365
...

Sheet Year-over-Year
A1: The Home Depot, Inc. | B1: ACTUAL | H1: FORECAST
A2: Year-over-Year Balance Sheet | B2: 43863 | C2: 44227 | D2: 44591 | E2: 44955 | F2: 45319 | G2: 45690 | H2: 46053 | I2: 46418 | J2: 46783 | K2: 47149 | L2: 47514
A4: ASSETS
A5: Cash and cash equivalents | C5: =(Financials!C5-Financials!B5)/Financials!B5 -> 2.7013596 | D5: =(Financials!D5-Financials!C5)/Financials!C5 -> -0.70322989 | E5: =(Financials!E5-Financials!D5)/Financials!D5 -> 0.17669654 | F5: =(Financials!F5-Financials!E5)/Financials!E5 -> 0.36380123 | G5: =(Financials!G5-Financials!F5)/Financials!F5 -> -0.5587766 | H5: =(Financials!H5-Financials!G5)/Financials!G5 -> 0.56720916 | I5: =(Financials!I5-Financials!H5)/Financials!H5 -> 0 | J5: =(Financials!J5-Financials!I5)/Financials!I5 -> 0 | ... L5: =(Financials!L5-Financials!K5)/Financials!K5 -> 0
A6: Short-term investments
A7: Receivables, net | C7: =(Financials!C7-Financials!B7)/Financials!B7 -> 0.42070275 | D7: =(Financials!D7-Financials!C7)/Financials!C7 -> 0.14505348 | E7: =(Financials!E7-Financials!D7)/Financials!D7 -> -0.031815528 | F7: =(Financials!F7-Financials!E7)/Financials!E7 -> 0.0033162496 | G7: =(Financials!G7-Financials!F7)/Financials!F7 -> 0.47325721 | H7: =(Financials!H7-Financials!G7)/Financials!G7 -> -0.23382877 | I7: =(Financials!I7-Financials!H7)/Financials!H7 -> 0.075845539 | J7: =(Financials!J7-Financials!I7)/Financials!I7 -> 0.075882286 | ... L7: =(Financials!L7-Financials!K7)/Financials!K7 -> 0.075955201
A8: Merchandise inventories | C8: =(Financials!C8-Financials!B8)/Financials!B8 -> 0.14424334 | D8: =(Financials!D8-Financials!C8)/Financials!C8 -> 0.32723883 | E8: =(Financials!E8-Financials!D8)/Financials!D8 -> 0.12769621 | F8: =(Financials!F8-Financials!E8)/Financials!E8 -> -0.15711645 | G8: =(Financials!G8-Financials!F8)/Financials!F8 -> 0.11799199 | H8: =(Financials!H8-Financials!G8)/Financials!G8 -> -0.007401558 | I8: =(Financials!I8-Financials!H8)/Financials!H8 -> 0.075845539 | J8: =(Financials!J8-Financials!I8)/Financials!I8 -> 0.075882286 | ... L8: =(Financials!L8-Financials!K8)/Financials!K8 -> 0.075955201
A9: Other current assets | C9: =(Financials!C9-Financials!B9)/Financials!B9 -> -0.074038462 | D9: =(Financials!D9-Financials!C9)/Financials!C9 -> 0.26479751 | E9: =(Financials!E9-Financials!D9)/Financials!D9 -> 0.24055829 | F9: =(Financials!F9-Financials!E9)/Financials!E9 -> 0.13236267 | G9: =(Financials!G9-Financials!F9)/Financials!F9 -> -0.023962595 | H9: =(Financials!H9-Financials!G9)/Financials!G9 -> -0.044346851 | I9: =(Financials!I9-Financials!H9)/Financials!H9 -> 0.075845539 | J9: =(Financials!J9-Financials!I9)/Financials!I9 -> 0.075882286 | ... L9: =(Financials!L9-Financials!K9)/Financials!K9 -> 0.075955201
A10: Total current assets | C10: =(Financials!C10-Financials!B10)/Financials!B10 -> 0.43750631 | D10: =(Financials!D10-Financials!C10)/Financials!C10 -> 0.020297082 | E10: =(Financials!E10-Financials!D10)/Financials!D10 -> 0.11757013 | F10: =(Financials!F10-Financials!E10)/Financials!E10 -> -0.083027933 | G10: =(Financials!G10-Financials!F10)/Financials!F10 -> 0.064080605 | H10: =(Financials!H10-Financials!G10)/Financials!G10 -> 0.016159555 | I10: =(Financials!I10-Financials!H10)/Financials!H10 -> 0.081934664 | J10: =(Financials!J10-Financials!I10)/Financials!I10 -> 0.16188199 | ... L10: =(Financials!L10-Financials!K10)/Financials!K10 -> 0.18663625
